2025-03-30 11:56:31,540 (INFO) - django.utils.autoreload - Watching for file changes with StatReloader
2025-03-30 11:56:49,840 (INFO) - django.utils.autoreload - Watching for file changes with StatReloader
2025-03-30 11:57:21,457 (INFO) - django.utils.autoreload - /home/iviidev/projects/aerten/aerten/settings/common.py changed, reloading.
2025-03-30 11:57:22,833 (INFO) - django.utils.autoreload - Watching for file changes with StatReloader
2025-03-30 11:58:37,931 (INFO) - django.utils.autoreload - /home/iviidev/projects/aerten/aerten/settings/common.py changed, reloading.
2025-03-30 11:58:39,195 (INFO) - django.utils.autoreload - Watching for file changes with StatReloader
2025-03-30 11:59:20,426 (WARNING) - django.request - Not Found: /favicon.ico
2025-03-30 11:59:24,814 (WARNING) - django.request - Not Found: /api/employees/
2025-03-30 11:59:33,885 (WARNING) - django.request - Unauthorized: /api/v1/employees/
2025-03-30 11:59:34,122 (WARNING) - django.request - Unauthorized: /api/v1/employees/
2025-03-30 11:59:45,967 (ERROR) - django.request - Internal Server Error: /api/v1/permissions/
Traceback (most recent call last):
  File "/home/iviidev/.local/share/virtualenvs/aerten-5eNgu6O3/lib/python3.12/site-packages/django_redis/cache.py", line 29, in _decorator
    return method(self, *args, **kwargs)
           ^^^^^^^^^^^^^^^^^^^^^^^^^^^^^
  File "/home/iviidev/.local/share/virtualenvs/aerten-5eNgu6O3/lib/python3.12/site-packages/django_redis/cache.py", line 99, in _get
    return self.client.get(key, default=default, version=version, client=client)
           ^^^^^^^^^^^^^^^^^^^^^^^^^^^^^^^^^^^^^^^^^^^^^^^^^^^^^^^^^^^^^^^^^^^^^
  File "/home/iviidev/.local/share/virtualenvs/aerten-5eNgu6O3/lib/python3.12/site-packages/django_redis/client/default.py", line 260, in get
    raise ConnectionInterrupted(connection=client) from e
django_redis.exceptions.ConnectionInterrupted: Redis ConnectionError: Error 111 connecting to 127.0.0.1:6379. Connection refused.

During handling of the above exception, another exception occurred:

Traceback (most recent call last):
  File "/home/iviidev/.local/share/virtualenvs/aerten-5eNgu6O3/lib/python3.12/site-packages/django/core/handlers/exception.py", line 55, in inner
    response = get_response(request)
               ^^^^^^^^^^^^^^^^^^^^^
  File "/home/iviidev/.local/share/virtualenvs/aerten-5eNgu6O3/lib/python3.12/site-packages/django/core/handlers/base.py", line 197, in _get_response
    response = wrapped_callback(request, *callback_args, **callback_kwargs)
               ^^^^^^^^^^^^^^^^^^^^^^^^^^^^^^^^^^^^^^^^^^^^^^^^^^^^^^^^^^^^
  File "/home/iviidev/.local/share/virtualenvs/aerten-5eNgu6O3/lib/python3.12/site-packages/django/views/decorators/csrf.py", line 65, in _view_wrapper
    return view_func(request, *args, **kwargs)
           ^^^^^^^^^^^^^^^^^^^^^^^^^^^^^^^^^^^
  File "/home/iviidev/.local/share/virtualenvs/aerten-5eNgu6O3/lib/python3.12/site-packages/rest_framework/viewsets.py", line 125, in view
    return self.dispatch(request, *args, **kwargs)
           ^^^^^^^^^^^^^^^^^^^^^^^^^^^^^^^^^^^^^^^
  File "/home/iviidev/.local/share/virtualenvs/aerten-5eNgu6O3/lib/python3.12/site-packages/rest_framework/views.py", line 515, in dispatch
    response = self.handle_exception(exc)
               ^^^^^^^^^^^^^^^^^^^^^^^^^^
  File "/home/iviidev/.local/share/virtualenvs/aerten-5eNgu6O3/lib/python3.12/site-packages/rest_framework/views.py", line 475, in handle_exception
    self.raise_uncaught_exception(exc)
  File "/home/iviidev/.local/share/virtualenvs/aerten-5eNgu6O3/lib/python3.12/site-packages/rest_framework/views.py", line 486, in raise_uncaught_exception
    raise exc
  File "/home/iviidev/.local/share/virtualenvs/aerten-5eNgu6O3/lib/python3.12/site-packages/rest_framework/views.py", line 512, in dispatch
    response = handler(request, *args, **kwargs)
               ^^^^^^^^^^^^^^^^^^^^^^^^^^^^^^^^^
  File "/home/iviidev/projects/aerten/employee_management/views.py", line 37, in list
    cached_permissions = cache.get(cache_key)
                         ^^^^^^^^^^^^^^^^^^^^
  File "/home/iviidev/.local/share/virtualenvs/aerten-5eNgu6O3/lib/python3.12/site-packages/debug_toolbar/panels/cache.py", line 42, in wrapper
    return panel._record_call(cache, name, original_method, args, kwargs)
           ^^^^^^^^^^^^^^^^^^^^^^^^^^^^^^^^^^^^^^^^^^^^^^^^^^^^^^^^^^^^^^
  File "/home/iviidev/.local/share/virtualenvs/aerten-5eNgu6O3/lib/python3.12/site-packages/debug_toolbar/panels/cache.py", line 151, in _record_call
    value = original_method(*args, **kwargs)
            ^^^^^^^^^^^^^^^^^^^^^^^^^^^^^^^^
  File "/home/iviidev/.local/share/virtualenvs/aerten-5eNgu6O3/lib/python3.12/site-packages/django_redis/cache.py", line 92, in get
    value = self._get(key, default, version, client)
            ^^^^^^^^^^^^^^^^^^^^^^^^^^^^^^^^^^^^^^^^
  File "/home/iviidev/.local/share/virtualenvs/aerten-5eNgu6O3/lib/python3.12/site-packages/django_redis/cache.py", line 36, in _decorator
    raise e.__cause__
  File "/home/iviidev/.local/share/virtualenvs/aerten-5eNgu6O3/lib/python3.12/site-packages/django_redis/client/default.py", line 258, in get
    value = client.get(key)
            ^^^^^^^^^^^^^^^
  File "/home/iviidev/.local/share/virtualenvs/aerten-5eNgu6O3/lib/python3.12/site-packages/redis/commands/core.py", line 1822, in get
    return self.execute_command("GET", name, keys=[name])
           ^^^^^^^^^^^^^^^^^^^^^^^^^^^^^^^^^^^^^^^^^^^^^^
  File "/home/iviidev/.local/share/virtualenvs/aerten-5eNgu6O3/lib/python3.12/site-packages/redis/client.py", line 559, in execute_command
    return self._execute_command(*args, **options)
           ^^^^^^^^^^^^^^^^^^^^^^^^^^^^^^^^^^^^^^^
  File "/home/iviidev/.local/share/virtualenvs/aerten-5eNgu6O3/lib/python3.12/site-packages/redis/client.py", line 565, in _execute_command
    conn = self.connection or pool.get_connection(command_name, **options)
                              ^^^^^^^^^^^^^^^^^^^^^^^^^^^^^^^^^^^^^^^^^^^^
  File "/home/iviidev/.local/share/virtualenvs/aerten-5eNgu6O3/lib/python3.12/site-packages/redis/connection.py", line 1422, in get_connection
    connection.connect()
  File "/home/iviidev/.local/share/virtualenvs/aerten-5eNgu6O3/lib/python3.12/site-packages/redis/connection.py", line 363, in connect
    raise ConnectionError(self._error_message(e))
redis.exceptions.ConnectionError: Error 111 connecting to 127.0.0.1:6379. Connection refused.
2025-03-30 12:02:30,384 (WARNING) - django.request - Unauthorized: /api/v1/teams/
2025-03-30 12:03:42,323 (WARNING) - django.request - Not Found: /api/v1/employees/99999/
2025-03-30 12:03:42,348 (WARNING) - django.request - Unauthorized: /api/v1/employees/B59E5C204B2B/
2025-03-30 12:03:44,114 (WARNING) - django.request - Forbidden: /api/v1/employees/8E4917C2617F/
2025-03-30 12:03:45,377 (WARNING) - django.request - Bad Request: /api/v1/employees/F2BAB8066BD8/
2025-03-30 12:03:48,563 (WARNING) - django.request - Not Found: /api/v1/employees/9999999/
2025-03-30 12:03:48,589 (WARNING) - django.request - Unauthorized: /api/v1/employees/CC1116F961EC/
2025-03-30 12:03:51,119 (WARNING) - django.request - Forbidden: /api/v1/employees/4306C0E298AB/
2025-03-30 12:03:53,469 (WARNING) - django.request - Not Found: /api/v1/employees/9999999/
2025-03-30 12:03:53,483 (WARNING) - django.request - Unauthorized: /api/v1/permissions/
2025-03-30 12:03:54,748 (WARNING) - django.request - Forbidden: /api/v1/permissions/
2025-03-30 12:03:56,128 (WARNING) - django.request - Bad Request: /api/v1/permissions/
2025-03-30 12:03:57,373 (WARNING) - django.request - Not Found: /api/v1/permissions/99999/
2025-03-30 12:03:57,392 (WARNING) - django.request - Unauthorized: /api/v1/permissions/3/
2025-03-30 12:03:58,933 (WARNING) - django.request - Forbidden: /api/v1/permissions/4/
2025-03-30 12:04:00,113 (WARNING) - django.request - Bad Request: /api/v1/permissions/5/
2025-03-30 12:04:02,678 (WARNING) - django.request - Not Found: /api/v1/permissions/9999999/
2025-03-30 12:04:02,694 (WARNING) - django.request - Unauthorized: /api/v1/permissions/7/
2025-03-30 12:04:03,846 (WARNING) - django.request - Forbidden: /api/v1/permissions/8/
2025-03-30 12:04:06,163 (WARNING) - django.request - Not Found: /api/v1/permissions/9999999/
2025-03-30 12:06:17,638 (INFO) - django.utils.autoreload - /home/iviidev/projects/aerten/aerten/settings/common.py changed, reloading.
2025-03-30 12:06:19,614 (INFO) - django.utils.autoreload - Watching for file changes with StatReloader
2025-03-30 12:06:44,355 (WARNING) - django.request - Not Found: /api/v1/employees/99999/
2025-03-30 12:06:44,414 (WARNING) - django.request - Unauthorized: /api/v1/employees/9F3AC0AEA4B7/
2025-03-30 12:06:46,077 (WARNING) - django.request - Forbidden: /api/v1/employees/09027B81C50D/
2025-03-30 12:06:47,324 (WARNING) - django.request - Bad Request: /api/v1/employees/FC131AD32BE4/
2025-03-30 12:06:49,621 (WARNING) - django.request - Not Found: /api/v1/employees/9999999/
2025-03-30 12:06:49,690 (WARNING) - django.request - Unauthorized: /api/v1/employees/D8FB73574CD1/
2025-03-30 12:06:50,742 (WARNING) - django.request - Forbidden: /api/v1/employees/C272F8615C6C/
2025-03-30 12:06:52,787 (WARNING) - django.request - Not Found: /api/v1/employees/9999999/
2025-03-30 12:06:52,840 (WARNING) - django.request - Unauthorized: /api/v1/permissions/
2025-03-30 12:06:53,864 (WARNING) - django.request - Forbidden: /api/v1/permissions/
2025-03-30 12:06:54,875 (WARNING) - django.request - Bad Request: /api/v1/permissions/
2025-03-30 12:06:56,257 (WARNING) - django.request - Not Found: /api/v1/permissions/99999/
2025-03-30 09:41:31,763 (WARNING) - django.request - Unauthorized: /api/v1/permissions/3/
2025-03-30 12:07:00,295 (WARNING) - django.request - Forbidden: /api/v1/permissions/4/
2025-03-30 12:07:01,398 (WARNING) - django.request - Bad Request: /api/v1/permissions/5/
2025-03-30 12:07:03,556 (WARNING) - django.request - Not Found: /api/v1/permissions/9999999/
2025-03-30 12:07:03,605 (WARNING) - django.request - Unauthorized: /api/v1/permissions/7/
2025-03-30 12:07:04,610 (WARNING) - django.request - Forbidden: /api/v1/permissions/8/
2025-03-30 12:07:06,603 (WARNING) - django.request - Not Found: /api/v1/permissions/9999999/
2025-03-30 12:14:02,261 (INFO) - django.utils.autoreload - Watching for file changes with StatReloader
2025-03-30 16:14:04,571 (INFO) - django.utils.autoreload - /home/iviidev/projects/aerten/aerten/settings/dev.py changed, reloading.
2025-03-30 16:14:07,779 (INFO) - django.utils.autoreload - Watching for file changes with StatReloader
2025-03-30 16:14:26,380 (INFO) - django.utils.autoreload - /home/iviidev/projects/aerten/aerten/settings/dev.py changed, reloading.
2025-03-30 20:34:35,210 (INFO) - django.utils.autoreload - Watching for file changes with StatReloader
2025-03-30 20:37:38,681 (INFO) - django.utils.autoreload - /home/iviidev/projects/aerten/aerten/settings.py changed, reloading.
2025-03-30 20:37:40,726 (INFO) - django.utils.autoreload - Watching for file changes with StatReloader
2025-03-30 20:38:28,538 (INFO) - django.utils.autoreload - /home/iviidev/projects/aerten/aerten/settings.py changed, reloading.
2025-03-30 20:38:30,927 (INFO) - django.utils.autoreload - Watching for file changes with StatReloader
2025-03-30 20:39:45,078 (INFO) - django.utils.autoreload - /home/iviidev/projects/aerten/aerten/settings.py changed, reloading.
2025-03-30 20:39:48,227 (INFO) - django.utils.autoreload - Watching for file changes with StatReloader
2025-03-30 20:41:37,214 (INFO) - django.utils.autoreload - /home/iviidev/projects/aerten/aerten/settings.py changed, reloading.
2025-03-30 20:41:39,466 (INFO) - django.utils.autoreload - Watching for file changes with StatReloader
2025-03-30 20:42:17,378 (INFO) - django.utils.autoreload - /home/iviidev/projects/aerten/aerten/settings.py changed, reloading.
2025-03-30 20:42:19,410 (INFO) - django.utils.autoreload - Watching for file changes with StatReloader
2025-03-30 20:42:58,721 (INFO) - django.utils.autoreload - /home/iviidev/projects/aerten/aerten/settings.py changed, reloading.
2025-03-30 20:43:00,068 (INFO) - django.utils.autoreload - Watching for file changes with StatReloader
2025-03-30 20:43:26,923 (INFO) - django.utils.autoreload - /home/iviidev/projects/aerten/aerten/settings.py changed, reloading.
2025-03-30 20:43:30,406 (INFO) - django.utils.autoreload - Watching for file changes with StatReloader
2025-03-30 20:43:33,580 (INFO) - django.utils.autoreload - /home/iviidev/projects/aerten/aerten/settings.py changed, reloading.
2025-03-30 20:43:35,440 (INFO) - django.utils.autoreload - Watching for file changes with StatReloader
2025-03-30 20:52:27,348 (INFO) - django.utils.autoreload - /home/iviidev/projects/aerten/aerten/settings.py changed, reloading.
2025-04-02 18:02:21,371 (INFO) - django.utils.autoreload - Watching for file changes with StatReloader
2025-04-02 18:02:50,578 (WARNING) - django.request - Not Found: /favicon.ico
2025-04-03 14:50:09,063 (INFO) - django.utils.autoreload - Watching for file changes with StatReloader
2025-04-03 14:51:52,168 (INFO) - django.utils.autoreload - Watching for file changes with StatReloader
2025-04-03 14:52:17,938 (INFO) - django.utils.autoreload - Watching for file changes with StatReloader
2025-04-03 14:52:30,811 (ERROR) - django.security.DisallowedHost - Invalid HTTP_HOST header: '127.0.0.1:8000'. You may need to add '127.0.0.1' to ALLOWED_HOSTS.
Traceback (most recent call last):
  File "/home/iviidev/.local/share/virtualenvs/aerten-5eNgu6O3/lib/python3.12/site-packages/django/core/handlers/exception.py", line 55, in inner
    response = get_response(request)
               ^^^^^^^^^^^^^^^^^^^^^
  File "/home/iviidev/.local/share/virtualenvs/aerten-5eNgu6O3/lib/python3.12/site-packages/django/utils/deprecation.py", line 128, in __call__
    response = self.process_request(request)
               ^^^^^^^^^^^^^^^^^^^^^^^^^^^^^
  File "/home/iviidev/.local/share/virtualenvs/aerten-5eNgu6O3/lib/python3.12/site-packages/django/middleware/common.py", line 48, in process_request
    host = request.get_host()
           ^^^^^^^^^^^^^^^^^^
  File "/home/iviidev/.local/share/virtualenvs/aerten-5eNgu6O3/lib/python3.12/site-packages/django/http/request.py", line 151, in get_host
    raise DisallowedHost(msg)
django.core.exceptions.DisallowedHost: Invalid HTTP_HOST header: '127.0.0.1:8000'. You may need to add '127.0.0.1' to ALLOWED_HOSTS.
2025-04-03 14:52:30,834 (WARNING) - django.request - Bad Request: /admin
2025-04-03 14:52:32,749 (ERROR) - django.security.DisallowedHost - Invalid HTTP_HOST header: '127.0.0.1:8000'. You may need to add '127.0.0.1' to ALLOWED_HOSTS.
Traceback (most recent call last):
  File "/home/iviidev/.local/share/virtualenvs/aerten-5eNgu6O3/lib/python3.12/site-packages/django/core/handlers/exception.py", line 55, in inner
    response = get_response(request)
               ^^^^^^^^^^^^^^^^^^^^^
  File "/home/iviidev/.local/share/virtualenvs/aerten-5eNgu6O3/lib/python3.12/site-packages/django/utils/deprecation.py", line 128, in __call__
    response = self.process_request(request)
               ^^^^^^^^^^^^^^^^^^^^^^^^^^^^^
  File "/home/iviidev/.local/share/virtualenvs/aerten-5eNgu6O3/lib/python3.12/site-packages/django/middleware/common.py", line 48, in process_request
    host = request.get_host()
           ^^^^^^^^^^^^^^^^^^
  File "/home/iviidev/.local/share/virtualenvs/aerten-5eNgu6O3/lib/python3.12/site-packages/django/http/request.py", line 151, in get_host
    raise DisallowedHost(msg)
django.core.exceptions.DisallowedHost: Invalid HTTP_HOST header: '127.0.0.1:8000'. You may need to add '127.0.0.1' to ALLOWED_HOSTS.
2025-04-03 14:52:32,751 (WARNING) - django.request - Bad Request: /favicon.ico
2025-04-03 14:52:59,567 (INFO) - django.utils.autoreload - /home/iviidev/projects/aerten/aerten/settings.py changed, reloading.
2025-04-03 14:53:00,929 (INFO) - django.utils.autoreload - Watching for file changes with StatReloader
2025-04-03 14:53:04,898 (INFO) - django.utils.autoreload - /home/iviidev/projects/aerten/aerten/settings.py changed, reloading.
2025-04-03 14:53:07,531 (INFO) - django.utils.autoreload - Watching for file changes with StatReloader
2025-04-03 14:53:09,539 (ERROR) - django.security.DisallowedHost - Invalid HTTP_HOST header: '127.0.0.1:8000'. You may need to add '127.0.0.1' to ALLOWED_HOSTS.
Traceback (most recent call last):
  File "/home/iviidev/.local/share/virtualenvs/aerten-5eNgu6O3/lib/python3.12/site-packages/django/core/handlers/exception.py", line 55, in inner
    response = get_response(request)
               ^^^^^^^^^^^^^^^^^^^^^
  File "/home/iviidev/.local/share/virtualenvs/aerten-5eNgu6O3/lib/python3.12/site-packages/django/utils/deprecation.py", line 128, in __call__
    response = self.process_request(request)
               ^^^^^^^^^^^^^^^^^^^^^^^^^^^^^
  File "/home/iviidev/.local/share/virtualenvs/aerten-5eNgu6O3/lib/python3.12/site-packages/django/middleware/common.py", line 48, in process_request
    host = request.get_host()
           ^^^^^^^^^^^^^^^^^^
  File "/home/iviidev/.local/share/virtualenvs/aerten-5eNgu6O3/lib/python3.12/site-packages/django/http/request.py", line 151, in get_host
    raise DisallowedHost(msg)
django.core.exceptions.DisallowedHost: Invalid HTTP_HOST header: '127.0.0.1:8000'. You may need to add '127.0.0.1' to ALLOWED_HOSTS.
2025-04-03 14:53:09,547 (WARNING) - django.request - Bad Request: /admin
2025-04-03 14:53:10,005 (ERROR) - django.security.DisallowedHost - Invalid HTTP_HOST header: '127.0.0.1:8000'. You may need to add '127.0.0.1' to ALLOWED_HOSTS.
Traceback (most recent call last):
  File "/home/iviidev/.local/share/virtualenvs/aerten-5eNgu6O3/lib/python3.12/site-packages/django/core/handlers/exception.py", line 55, in inner
    response = get_response(request)
               ^^^^^^^^^^^^^^^^^^^^^
  File "/home/iviidev/.local/share/virtualenvs/aerten-5eNgu6O3/lib/python3.12/site-packages/django/utils/deprecation.py", line 128, in __call__
    response = self.process_request(request)
               ^^^^^^^^^^^^^^^^^^^^^^^^^^^^^
  File "/home/iviidev/.local/share/virtualenvs/aerten-5eNgu6O3/lib/python3.12/site-packages/django/middleware/common.py", line 48, in process_request
    host = request.get_host()
           ^^^^^^^^^^^^^^^^^^
  File "/home/iviidev/.local/share/virtualenvs/aerten-5eNgu6O3/lib/python3.12/site-packages/django/http/request.py", line 151, in get_host
    raise DisallowedHost(msg)
django.core.exceptions.DisallowedHost: Invalid HTTP_HOST header: '127.0.0.1:8000'. You may need to add '127.0.0.1' to ALLOWED_HOSTS.
2025-04-03 14:53:10,009 (WARNING) - django.request - Bad Request: /favicon.ico
2025-04-03 14:53:29,225 (INFO) - django.utils.autoreload - /home/iviidev/projects/aerten/aerten/settings.py changed, reloading.
2025-04-03 14:53:30,648 (INFO) - django.utils.autoreload - Watching for file changes with StatReloader
2025-04-03 14:53:35,724 (WARNING) - django.request - Not Found: /favicon.ico
2025-04-03 14:53:57,211 (ERROR) - django.request - Internal Server Error: /admin/employee_management/employee/
Traceback (most recent call last):
  File "/home/iviidev/.local/share/virtualenvs/aerten-5eNgu6O3/lib/python3.12/site-packages/django/db/models/options.py", line 676, in get_field
    return self.fields_map[field_name]
           ~~~~~~~~~~~~~~~^^^^^^^^^^^^
KeyError: 'get_role'

During handling of the above exception, another exception occurred:

Traceback (most recent call last):
  File "/home/iviidev/.local/share/virtualenvs/aerten-5eNgu6O3/lib/python3.12/site-packages/django/contrib/admin/utils.py", line 290, in lookup_field
    f = _get_non_gfk_field(opts, name)
        ^^^^^^^^^^^^^^^^^^^^^^^^^^^^^^
  File "/home/iviidev/.local/share/virtualenvs/aerten-5eNgu6O3/lib/python3.12/site-packages/django/contrib/admin/utils.py", line 330, in _get_non_gfk_field
    field = opts.get_field(name)
            ^^^^^^^^^^^^^^^^^^^^
  File "/home/iviidev/.local/share/virtualenvs/aerten-5eNgu6O3/lib/python3.12/site-packages/django/db/models/options.py", line 678, in get_field
    raise FieldDoesNotExist(
django.core.exceptions.FieldDoesNotExist: Employee has no field named 'get_role'

During handling of the above exception, another exception occurred:

Traceback (most recent call last):
  File "/home/iviidev/.local/share/virtualenvs/aerten-5eNgu6O3/lib/python3.12/site-packages/django/core/handlers/exception.py", line 55, in inner
    response = get_response(request)
               ^^^^^^^^^^^^^^^^^^^^^
  File "/home/iviidev/.local/share/virtualenvs/aerten-5eNgu6O3/lib/python3.12/site-packages/django/core/handlers/base.py", line 220, in _get_response
    response = response.render()
               ^^^^^^^^^^^^^^^^^
  File "/home/iviidev/.local/share/virtualenvs/aerten-5eNgu6O3/lib/python3.12/site-packages/django/template/response.py", line 114, in render
    self.content = self.rendered_content
                   ^^^^^^^^^^^^^^^^^^^^^
  File "/home/iviidev/.local/share/virtualenvs/aerten-5eNgu6O3/lib/python3.12/site-packages/django/template/response.py", line 92, in rendered_content
    return template.render(context, self._request)
           ^^^^^^^^^^^^^^^^^^^^^^^^^^^^^^^^^^^^^^^
  File "/home/iviidev/.local/share/virtualenvs/aerten-5eNgu6O3/lib/python3.12/site-packages/django/template/backends/django.py", line 107, in render
    return self.template.render(context)
           ^^^^^^^^^^^^^^^^^^^^^^^^^^^^^
  File "/home/iviidev/.local/share/virtualenvs/aerten-5eNgu6O3/lib/python3.12/site-packages/django/template/base.py", line 171, in render
    return self._render(context)
           ^^^^^^^^^^^^^^^^^^^^^
  File "/home/iviidev/.local/share/virtualenvs/aerten-5eNgu6O3/lib/python3.12/site-packages/django/test/utils.py", line 114, in instrumented_test_render
    return self.nodelist.render(context)
           ^^^^^^^^^^^^^^^^^^^^^^^^^^^^^
  File "/home/iviidev/.local/share/virtualenvs/aerten-5eNgu6O3/lib/python3.12/site-packages/django/template/base.py", line 1008, in render
    return SafeString("".join([node.render_annotated(context) for node in self]))
                               ^^^^^^^^^^^^^^^^^^^^^^^^^^^^^^
  File "/home/iviidev/.local/share/virtualenvs/aerten-5eNgu6O3/lib/python3.12/site-packages/django/template/base.py", line 969, in render_annotated
    return self.render(context)
           ^^^^^^^^^^^^^^^^^^^^
  File "/home/iviidev/.local/share/virtualenvs/aerten-5eNgu6O3/lib/python3.12/site-packages/django/template/loader_tags.py", line 159, in render
    return compiled_parent._render(context)
           ^^^^^^^^^^^^^^^^^^^^^^^^^^^^^^^^
  File "/home/iviidev/.local/share/virtualenvs/aerten-5eNgu6O3/lib/python3.12/site-packages/django/test/utils.py", line 114, in instrumented_test_render
    return self.nodelist.render(context)
           ^^^^^^^^^^^^^^^^^^^^^^^^^^^^^
  File "/home/iviidev/.local/share/virtualenvs/aerten-5eNgu6O3/lib/python3.12/site-packages/django/template/base.py", line 1008, in render
    return SafeString("".join([node.render_annotated(context) for node in self]))
                               ^^^^^^^^^^^^^^^^^^^^^^^^^^^^^^
  File "/home/iviidev/.local/share/virtualenvs/aerten-5eNgu6O3/lib/python3.12/site-packages/django/template/base.py", line 969, in render_annotated
    return self.render(context)
           ^^^^^^^^^^^^^^^^^^^^
  File "/home/iviidev/.local/share/virtualenvs/aerten-5eNgu6O3/lib/python3.12/site-packages/django/template/loader_tags.py", line 159, in render
    return compiled_parent._render(context)
           ^^^^^^^^^^^^^^^^^^^^^^^^^^^^^^^^
  File "/home/iviidev/.local/share/virtualenvs/aerten-5eNgu6O3/lib/python3.12/site-packages/django/test/utils.py", line 114, in instrumented_test_render
    return self.nodelist.render(context)
           ^^^^^^^^^^^^^^^^^^^^^^^^^^^^^
  File "/home/iviidev/.local/share/virtualenvs/aerten-5eNgu6O3/lib/python3.12/site-packages/django/template/base.py", line 1008, in render
    return SafeString("".join([node.render_annotated(context) for node in self]))
                               ^^^^^^^^^^^^^^^^^^^^^^^^^^^^^^
  File "/home/iviidev/.local/share/virtualenvs/aerten-5eNgu6O3/lib/python3.12/site-packages/django/template/base.py", line 969, in render_annotated
    return self.render(context)
           ^^^^^^^^^^^^^^^^^^^^
  File "/home/iviidev/.local/share/virtualenvs/aerten-5eNgu6O3/lib/python3.12/site-packages/django/template/loader_tags.py", line 65, in render
    result = block.nodelist.render(context)
             ^^^^^^^^^^^^^^^^^^^^^^^^^^^^^^
  File "/home/iviidev/.local/share/virtualenvs/aerten-5eNgu6O3/lib/python3.12/site-packages/django/template/base.py", line 1008, in render
    return SafeString("".join([node.render_annotated(context) for node in self]))
                               ^^^^^^^^^^^^^^^^^^^^^^^^^^^^^^
  File "/home/iviidev/.local/share/virtualenvs/aerten-5eNgu6O3/lib/python3.12/site-packages/django/template/base.py", line 969, in render_annotated
    return self.render(context)
           ^^^^^^^^^^^^^^^^^^^^
  File "/home/iviidev/.local/share/virtualenvs/aerten-5eNgu6O3/lib/python3.12/site-packages/django/template/loader_tags.py", line 65, in render
    result = block.nodelist.render(context)
             ^^^^^^^^^^^^^^^^^^^^^^^^^^^^^^
  File "/home/iviidev/.local/share/virtualenvs/aerten-5eNgu6O3/lib/python3.12/site-packages/django/template/base.py", line 1008, in render
    return SafeString("".join([node.render_annotated(context) for node in self]))
                               ^^^^^^^^^^^^^^^^^^^^^^^^^^^^^^
  File "/home/iviidev/.local/share/virtualenvs/aerten-5eNgu6O3/lib/python3.12/site-packages/django/template/base.py", line 969, in render_annotated
    return self.render(context)
           ^^^^^^^^^^^^^^^^^^^^
  File "/home/iviidev/.local/share/virtualenvs/aerten-5eNgu6O3/lib/python3.12/site-packages/django/contrib/admin/templatetags/base.py", line 45, in render
    return super().render(context)
           ^^^^^^^^^^^^^^^^^^^^^^^
  File "/home/iviidev/.local/share/virtualenvs/aerten-5eNgu6O3/lib/python3.12/site-packages/django/template/library.py", line 258, in render
    _dict = self.func(*resolved_args, **resolved_kwargs)
            ^^^^^^^^^^^^^^^^^^^^^^^^^^^^^^^^^^^^^^^^^^^^
  File "/home/iviidev/.local/share/virtualenvs/aerten-5eNgu6O3/lib/python3.12/site-packages/django/contrib/admin/templatetags/admin_list.py", line 346, in result_list
    "results": list(results(cl)),
               ^^^^^^^^^^^^^^^^^
  File "/home/iviidev/.local/share/virtualenvs/aerten-5eNgu6O3/lib/python3.12/site-packages/django/contrib/admin/templatetags/admin_list.py", line 319, in results
    yield ResultList(form, items_for_result(cl, res, form))
          ^^^^^^^^^^^^^^^^^^^^^^^^^^^^^^^^^^^^^^^^^^^^^^^^^
  File "/home/iviidev/.local/share/virtualenvs/aerten-5eNgu6O3/lib/python3.12/site-packages/django/contrib/admin/templatetags/admin_list.py", line 313, in __init__
    super().__init__(*items)
  File "/home/iviidev/.local/share/virtualenvs/aerten-5eNgu6O3/lib/python3.12/site-packages/django/contrib/admin/templatetags/admin_list.py", line 218, in items_for_result
    f, attr, value = lookup_field(field_name, result, cl.model_admin)
                     ^^^^^^^^^^^^^^^^^^^^^^^^^^^^^^^^^^^^^^^^^^^^^^^^
  File "/home/iviidev/.local/share/virtualenvs/aerten-5eNgu6O3/lib/python3.12/site-packages/django/contrib/admin/utils.py", line 299, in lookup_field
    value = attr(obj)
            ^^^^^^^^^
  File "/home/iviidev/projects/aerten/employee_management/admin.py", line 39, in get_role
    return employee.role.title
           ^^^^^^^^^^^^^^^^^^^
AttributeError: 'NoneType' object has no attribute 'title'
2025-04-03 14:55:37,422 (INFO) - django.utils.autoreload - /home/iviidev/projects/aerten/employee_management/admin.py changed, reloading.
2025-04-03 14:55:38,457 (INFO) - django.utils.autoreload - Watching for file changes with StatReloader
2025-04-03 14:58:39,610 (INFO) - django.utils.autoreload - /home/iviidev/projects/aerten/employee_management/admin.py changed, reloading.
2025-04-03 14:58:41,258 (INFO) - django.utils.autoreload - Watching for file changes with StatReloader
2025-04-03 15:19:01,007 (INFO) - django.utils.autoreload - Watching for file changes with StatReloader
2025-04-03 15:19:51,347 (INFO) - django.utils.autoreload - /home/iviidev/projects/aerten/aerten/settings/common.py changed, reloading.
2025-04-03 15:19:52,709 (INFO) - django.utils.autoreload - Watching for file changes with StatReloader
2025-04-03 15:20:26,360 (WARNING) - django.request - Not Found: /api/v1/employees/99999/
2025-04-03 15:20:26,455 (WARNING) - django.request - Unauthorized: /api/v1/employees/7841391CC0B0/
2025-04-03 15:20:27,971 (WARNING) - django.request - Forbidden: /api/v1/employees/493250154037/
2025-04-03 15:20:31,353 (WARNING) - django.request - Bad Request: /api/v1/employees/00C7BA34B294/
2025-04-03 15:20:34,426 (WARNING) - django.request - Not Found: /api/v1/employees/9999999/
2025-04-03 15:20:34,516 (WARNING) - django.request - Unauthorized: /api/v1/employees/AAC24C2E7B3D/
2025-04-03 15:20:36,107 (WARNING) - django.request - Forbidden: /api/v1/employees/235EB0CF4564/
2025-04-03 15:20:39,224 (WARNING) - django.request - Not Found: /api/v1/employees/9999999/
2025-04-03 15:20:39,564 (WARNING) - django.request - Unauthorized: /api/v1/permissions/
2025-04-03 15:20:40,981 (WARNING) - django.request - Forbidden: /api/v1/permissions/
2025-04-03 15:20:42,210 (WARNING) - django.request - Bad Request: /api/v1/permissions/
2025-04-03 15:20:43,698 (WARNING) - django.request - Not Found: /api/v1/permissions/99999/
2025-04-03 15:20:43,750 (WARNING) - django.request - Unauthorized: /api/v1/permissions/3/
2025-04-03 15:20:45,102 (WARNING) - django.request - Forbidden: /api/v1/permissions/4/
2025-04-03 15:20:46,592 (WARNING) - django.request - Bad Request: /api/v1/permissions/5/
2025-04-03 15:20:51,581 (WARNING) - django.request - Not Found: /api/v1/permissions/9999999/
2025-04-03 15:20:51,729 (WARNING) - django.request - Unauthorized: /api/v1/permissions/7/
2025-04-03 15:20:53,588 (WARNING) - django.request - Forbidden: /api/v1/permissions/8/
2025-04-03 15:20:56,886 (WARNING) - django.request - Not Found: /api/v1/permissions/9999999/
2025-04-03 15:25:30,796 (INFO) - django.utils.autoreload - /home/iviidev/projects/aerten/aerten/settings/dev.py changed, reloading.
2025-04-03 15:25:32,030 (INFO) - django.utils.autoreload - Watching for file changes with StatReloader
2025-04-03 15:53:15,377 (INFO) - django.utils.autoreload - Watching for file changes with StatReloader
2025-04-03 15:54:58,818 (INFO) - django.utils.autoreload - Watching for file changes with StatReloader
2025-04-03 15:55:09,397 (INFO) - django.utils.autoreload - Watching for file changes with StatReloader
2025-04-03 15:56:13,828 (INFO) - django.utils.autoreload - Watching for file changes with StatReloader
2025-04-05 15:55:07,106 (INFO) - django.utils.autoreload - Watching for file changes with StatReloader
2025-04-05 15:55:26,434 (INFO) - django.utils.autoreload - Watching for file changes with StatReloader
2025-04-05 15:56:41,204 (INFO) - django.utils.autoreload - /home/iviidev/projects/aerten/employee_management/serializers.py changed, reloading.
2025-04-05 15:56:43,133 (INFO) - django.utils.autoreload - Watching for file changes with StatReloader
2025-04-05 15:57:11,170 (INFO) - django.utils.autoreload - /home/iviidev/projects/aerten/employee_management/serializers.py changed, reloading.
2025-04-05 15:57:15,834 (INFO) - django.utils.autoreload - Watching for file changes with StatReloader
2025-04-05 15:57:55,790 (INFO) - django.utils.autoreload - /home/iviidev/projects/aerten/employee_management/serializers.py changed, reloading.
2025-04-05 15:57:57,966 (INFO) - django.utils.autoreload - Watching for file changes with StatReloader
2025-04-05 15:58:23,079 (INFO) - django.utils.autoreload - /home/iviidev/projects/aerten/employee_management/serializers.py changed, reloading.
2025-04-05 15:58:24,839 (INFO) - django.utils.autoreload - Watching for file changes with StatReloader
2025-04-05 16:12:04,499 (WARNING) - django.request - Unauthorized: /auth/users/me/
2025-04-05 16:12:10,316 (WARNING) - django.request - Not Found: /favicon.ico
2025-04-05 16:12:21,529 (WARNING) - django.request - Method Not Allowed: /auth/jwt/create/
2025-04-05 16:12:21,897 (WARNING) - django.request - Method Not Allowed: /auth/jwt/create/
2025-04-05 16:13:14,512 (WARNING) - django.request - Not Found: /api/employees/me/
2025-04-05 16:14:07,982 (INFO) - django.utils.autoreload - /home/iviidev/projects/aerten/employee_management/serializers.py changed, reloading.
2025-04-05 16:14:10,222 (INFO) - django.utils.autoreload - Watching for file changes with StatReloader
2025-04-05 16:15:24,063 (WARNING) - django.request - Unauthorized: /api/v1/roles/
2025-04-05 18:14:50,306 (INFO) - django.utils.autoreload - Watching for file changes with StatReloader
2025-04-05 18:15:19,898 (WARNING) - django.request - Unauthorized: /auth/users/
2025-04-05 18:15:22,901 (WARNING) - django.request - Not Found: /favicon.ico
2025-04-05 18:16:01,464 (INFO) - django.utils.autoreload - Watching for file changes with StatReloader
2025-04-05 18:16:21,125 (WARNING) - django.request - Unauthorized: /api/v1/employees/
2025-04-05 18:17:11,132 (WARNING) - django.request - Unauthorized: /auth/jwt/create/
2025-04-05 18:17:46,201 (ERROR) - django.request - Internal Server Error: /api/v1/employees/
Traceback (most recent call last):
  File "/home/iviidev/.local/share/virtualenvs/aerten-5eNgu6O3/lib/python3.12/site-packages/django/core/handlers/exception.py", line 55, in inner
    response = get_response(request)
               ^^^^^^^^^^^^^^^^^^^^^
  File "/home/iviidev/.local/share/virtualenvs/aerten-5eNgu6O3/lib/python3.12/site-packages/django/core/handlers/base.py", line 197, in _get_response
    response = wrapped_callback(request, *callback_args, **callback_kwargs)
               ^^^^^^^^^^^^^^^^^^^^^^^^^^^^^^^^^^^^^^^^^^^^^^^^^^^^^^^^^^^^
  File "/home/iviidev/.local/share/virtualenvs/aerten-5eNgu6O3/lib/python3.12/site-packages/django/views/decorators/csrf.py", line 65, in _view_wrapper
    return view_func(request, *args, **kwargs)
           ^^^^^^^^^^^^^^^^^^^^^^^^^^^^^^^^^^^
  File "/home/iviidev/.local/share/virtualenvs/aerten-5eNgu6O3/lib/python3.12/site-packages/rest_framework/viewsets.py", line 125, in view
    return self.dispatch(request, *args, **kwargs)
           ^^^^^^^^^^^^^^^^^^^^^^^^^^^^^^^^^^^^^^^
  File "/home/iviidev/.local/share/virtualenvs/aerten-5eNgu6O3/lib/python3.12/site-packages/rest_framework/views.py", line 515, in dispatch
    response = self.handle_exception(exc)
               ^^^^^^^^^^^^^^^^^^^^^^^^^^
  File "/home/iviidev/.local/share/virtualenvs/aerten-5eNgu6O3/lib/python3.12/site-packages/rest_framework/views.py", line 475, in handle_exception
    self.raise_uncaught_exception(exc)
  File "/home/iviidev/.local/share/virtualenvs/aerten-5eNgu6O3/lib/python3.12/site-packages/rest_framework/views.py", line 486, in raise_uncaught_exception
    raise exc
  File "/home/iviidev/.local/share/virtualenvs/aerten-5eNgu6O3/lib/python3.12/site-packages/rest_framework/views.py", line 512, in dispatch
    response = handler(request, *args, **kwargs)
               ^^^^^^^^^^^^^^^^^^^^^^^^^^^^^^^^^
  File "/home/iviidev/.local/share/virtualenvs/aerten-5eNgu6O3/lib/python3.12/site-packages/rest_framework/mixins.py", line 43, in list
    return self.get_paginated_response(serializer.data)
                                       ^^^^^^^^^^^^^^^
  File "/home/iviidev/.local/share/virtualenvs/aerten-5eNgu6O3/lib/python3.12/site-packages/rest_framework/serializers.py", line 797, in data
    ret = super().data
          ^^^^^^^^^^^^
  File "/home/iviidev/.local/share/virtualenvs/aerten-5eNgu6O3/lib/python3.12/site-packages/rest_framework/serializers.py", line 251, in data
    self._data = self.to_representation(self.instance)
                 ^^^^^^^^^^^^^^^^^^^^^^^^^^^^^^^^^^^^^
  File "/home/iviidev/.local/share/virtualenvs/aerten-5eNgu6O3/lib/python3.12/site-packages/rest_framework/serializers.py", line 716, in to_representation
    self.child.to_representation(item) for item in iterable
    ^^^^^^^^^^^^^^^^^^^^^^^^^^^^^^^^^^
  File "/home/iviidev/.local/share/virtualenvs/aerten-5eNgu6O3/lib/python3.12/site-packages/rest_framework/serializers.py", line 525, in to_representation
    for field in fields:
  File "/home/iviidev/.local/share/virtualenvs/aerten-5eNgu6O3/lib/python3.12/site-packages/rest_framework/serializers.py", line 386, in _readable_fields
    for field in self.fields.values():
                 ^^^^^^^^^^^
  File "/home/iviidev/.local/share/virtualenvs/aerten-5eNgu6O3/lib/python3.12/site-packages/django/utils/functional.py", line 47, in __get__
    res = instance.__dict__[self.name] = self.func(instance)
                                         ^^^^^^^^^^^^^^^^^^^
  File "/home/iviidev/.local/share/virtualenvs/aerten-5eNgu6O3/lib/python3.12/site-packages/rest_framework/serializers.py", line 374, in fields
    for key, value in self.get_fields().items():
                      ^^^^^^^^^^^^^^^^^
  File "/home/iviidev/.local/share/virtualenvs/aerten-5eNgu6O3/lib/python3.12/site-packages/rest_framework/serializers.py", line 1081, in get_fields
    field_names = self.get_field_names(declared_fields, info)
                  ^^^^^^^^^^^^^^^^^^^^^^^^^^^^^^^^^^^^^^^^^^^
  File "/home/iviidev/.local/share/virtualenvs/aerten-5eNgu6O3/lib/python3.12/site-packages/rest_framework/serializers.py", line 1177, in get_field_names
    assert field_name in fields, (
           ^^^^^^^^^^^^^^^^^^^^
AssertionError: The field 'user' was declared on serializer EmployeeSerializer, but has not been included in the 'fields' option.
2025-04-05 18:18:10,447 (INFO) - django.utils.autoreload - /home/iviidev/projects/aerten/employee_management/serializers.py changed, reloading.
2025-04-05 18:18:13,850 (INFO) - django.utils.autoreload - Watching for file changes with StatReloader
2025-04-05 19:44:20,236 (INFO) - django.utils.autoreload - Watching for file changes with StatReloader
2025-04-05 19:44:32,372 (INFO) - django.utils.autoreload - Watching for file changes with StatReloader
2025-04-05 19:48:53,564 (WARNING) - django.request - Forbidden: /api/v1/employees/assign_role/
